import { create } from "zustand";
import { axiosInstance } from "../lib/axios.js";
import toast from "react-hot-toast";
import { io } from "socket.io-client";

const BASE_URL = "https://chat-fawn-gamma.vercel.app";

export const useAuthStore = create((set, get) => ({
  authUser: null,
  isSigningUp: false,
  isLoggingIn: false,
  isUpdatingProfile: false,
  isCheckingAuth: true,
  onlineUsers: [],
  socket: null,

  checkAuth: async () => {
    try {
      const res = await axiosInstance.get("/auth/check");
      set({ authUser: res.data });
      get().connectSocket();
    } catch (error) {
      console.log("Error in checkAuth:", error);
      set({ authUser: null });
    } finally {
      set({ isCheckingAuth: false });
    }
  },

  signup: async (data) => {
    set({ isSigningUp: true });
    try {
      const res = await axiosInstance.post("/auth/signup", data);
      set({ authUser: res.data });
      toast.success("Account created successfully");
      get().connectSocket();
    } catch (error) {
      const errorMessage = error.response
        ? error.response.data.message
        : "An unexpected error occurred. Please try again later.";
      toast.error(errorMessage);
    } finally {
      set({ isSigningUp: false });
    }
  },

  login: async (data) => {
    set({ isLoggingIn: true });
    try {
      const res = await axiosInstance.post("/auth/login", data);
      set({ authUser: res.data });
      toast.success("Logged in successfully");
      get().connectSocket();
    } catch (error) {
      const errorMessage = error.response
        ? error.response.data.message
        : "An unexpected error occurred. Please try again later.";
      toast.error(errorMessage);
    } finally {
      set({ isLoggingIn: false });
    }
  },

  logout: async () => {
    try {
      await axiosInstance.post("/auth/logout");
      set({ authUser: null });
      toast.success("Logged out successfully");
      get().disconnectSocket();
    } catch (error) {
      const errorMessage = error.response
        ? error.response.data.message
        : "An unexpected error occurred. Please try again later.";
      toast.error(errorMessage);
    }
  },

  updateProfile: async (data) => {
    set({ isUpdatingProfile: true });
    try {
      const res = await axiosInstance.put("/auth/update-profile", data);
      set({ authUser: res.data });
      toast.success("Profile updated successfully");
    } catch (error) {
      const errorMessage = error.response
        ? error.response.data.message
        : "An unexpected error occurred. Please try again later.";
      toast.error(errorMessage);
    } finally {
      set({ isUpdatingProfile: false });
    }
  },

  connectSocket: () => {
    const { authUser } = get();
    if (!authUser || get().socket?.connected) return;

    // Log socket connection attempt
    console.log("Connecting socket with userId:", authUser._id);

    const socket = io(BASE_URL, {
      query: {
        userId: authUser._id,
      },
    });
    socket.connect();

    set({ socket: socket });

    socket.on("getOnlineUsers", (userIds) => {
      set({ onlineUsers: userIds });
    });
  },

  disconnectSocket: () => {
    if (get().socket?.connected) get().socket.disconnect();
  },
}));
